Workbook

Sheet 初始
A1: 涡 街 流 量 计 测 量 记 录 (脉冲已知系数)
A2: 委托单位 | B2: / | G2: 型号规格 | H2: LUGB 015YDMEJCX2BB-401N15NN4 | O2: 证书编号 | P2: 2026E70-40-
A3: 样品名称 | B3: 涡街流量计 | G3: 出厂编号 | H3: 2026010023 | O3: 准确度 | P3: 1.0级
A4: 制造单位 | B4: 上海自仪海莱特流量仪表有限公司 | G4: 流量范围 | H4: ( 3.2～32 )m^3/h | O4: 外观密封 | P4: 合格
A5: 测量依据 | B5: JJG 1029-2007《涡街流量计》 | G5: 脉冲当量 | H5: 340.673 1/L | O5: 测量结果 | P5: qt≤q＜qmax | Q5: qmin≤q＜qt
A6: 环境温度 | B6: (20-21)℃ | D6: 环境湿度 | E6: (68-70)%RH | O6: 示值误差 | P6: -1.95% | Q6: -1.75%
A7: 测量介质 | B7: 空气 | D7: 其它 | E7: / | O7: 重 复 性 | P7: 0.06% | Q7: 0.23%
A8: 介质温度 | B8: 20.84℃ | D8: 介质压力 | E8: 94.380kPa | G8: 脉冲已知 | H8: 涡街流量计
A9: 测量用标准器名称：标准表法气体流量标准装置 扩展不确定度：0.3% 流量范围 m^3/h 证书编号： | O9: 测量结论 | P9: 示值误差 不合格
A12: 检测 | B12: 序号 | C12: 检测 | D12: 标准表 | E12: 标准表在 | F12: 标准表在 | G12: 被检表 | H12: 被检表 | L12: 频率 | M12: 被测 | N12: 被测体积 | O12: 示值误差 | P12: 示值误差 | Q12: 重复性
A13: 流量点 | C13: 时间 | D13: 示值 | E13: 被检处流量 | F13: 被检处体积 | G13: 压力 | H13: 温度 | M13: 脉冲
A14: m^3/h | C14: s | D14: L | E14: m^3/h | F14: L | G14: kPa | H14: ℃ | L14: Hz | M14: N | N14: L | O14: % | P14: % | Q14: %
A15: 32 | B15: 1 | C15: 44.1633 | D15: 389.323 | E15: 31.6937 | F15: 388.805 | G15: 94.380 | H15: 20.84 | L15: 3007.1 | M15: 132805 | N15: 389.831 | O15: 0.26 | P15: -1.73 | Q15: 0.03
B16: 2 | C16: 44.0693 | D16: 387.156 | E16: 31.5947 | F16: 386.766 | G16: 94.420 | H16: 20.97 | L16: 2997.5 | M16: 132096 | N16: 387.750 | O16: 0.25
B17: 3 | C17: 45.3182 | D17: 396.845 | E17: 31.4974 | F17: 396.502 | G17: 94.437 | H17: 21.03 | L17: 2990.0 | M17: 135502 | N17: 397.748 | O17: 0.31
A18: 31.43 | B18: 1 | C18: 44.0230 | D18: 385.482 | E18: 31.4943 | F18: 385.132 | G18: 94.456 | H18: 21.04 | L18: 2980.1 | M18: 131191 | N18: 385.094 | O18: -0.01 | P18: -1.95 | Q18: 0.05
B19: 2 | C19: 44.8496 | D19: 391.682 | E19: 31.4094 | F19: 391.305 | G19: 94.485 | H19: 21.03 | L19: 2974.1 | M19: 133385 | N19: 391.534 | O19: 0.06
B20: 3 | C20: 43.8205 | D20: 382.288 | E20: 31.3725 | F20: 381.877 | G20: 94.498 | H20: 21.00 | L20: 2971.6 | M20: 130216 | N20: 382.232 | O20: 0.09
A21: 12.57 | B21: 1 | C21: 44.5542 | D21: 155.320 | E21: 12.5531 | F21: 155.359 | G21: 99.291 | H21: 20.95 | L21: 1193.1 | M21: 53159 | N21: 156.041 | O21: 0.44 | P21: -1.64 | Q21: 0.06
B22: 2 | C22: 44.3993 | D22: 154.879 | E22: 12.5606 | F22: 154.912 | G22: 99.289 | H22: 20.91 | L22: 1192.7 | M22: 52957 | N22: 155.448 | O22: 0.35
B23: 3 | C23: 44.5693 | D23: 156.099 | E23: 12.6100 | F23: 156.116 | G23: 99.285 | H23: 20.87 | L23: 1197.2 | M23: 53359 | N23: 156.628 | O23: 0.33
A24: 12.66 | B24: 1 | C24: 44.9286 | D24: 157.853 | E24: 12.6489 | F24: 157.861 | G24: 99.277 | H24: 20.84 | L24: 1200.5 | M24: 53936 | N24: 158.322 | O24: 0.29 | P24: -1.65 | Q24: 0.06
B25: 2 | C25: 44.5220 | D25: 156.806 | E25: 12.6789 | F25: 156.802 | G25: 99.262 | H25: 20.81 | L25: 1204.8 | M25: 53642 | N25: 157.459 | O25: 0.42
B26: 3 | C26: 44.4912 | D26: 156.255 | E26: 12.6424 | F26: 156.243 | G26: 99.276 | H26: 20.78 | L26: 1200.7 | M26: 53421 | N26: 156.810 | O26: 0.36
A27: 6.4 | B27: 1 | C27: 44.1621 | D27: 80.6446 | E27: 6.57469 | F27: 80.6534 | G27: 100.027 | H27: 20.76 | L27: 624.0 | M27: 27558 | N27: 80.8928 | O27: 0.30 | P27: -1.75 | Q27: 0.06
B28: 2 | C28: 44.1943 | D28: 81.3077 | E28: 6.62362 | F28: 81.3129 | G28: 100.034 | H28: 20.75 | L28: 628.6 | M28: 27779 | N28: 81.5415 | O28: 0.28
B29: 3 | C29: 44.9284 | D29: 82.3208 | E29: 6.59661 | F29: 82.3264 | G29: 100.036 | H29: 20.73 | L29: 625.4 | M29: 28099 | N29: 82.4809 | O29: 0.19
A30: 6.617 | B30: 1 | C30: 44.5206 | D30: 82.2474 | E30: 6.65098 | F30: 82.2516 | G30: 100.021 | H30: 20.72 | L30: 632.3 | M30: 28150 | N30: 82.6306 | O30: 0.46 | P30: -1.63 | Q30: 0.23
B31: 2 | C31: 44.3506 | D31: 81.7143 | E31: 6.63310 | F31: 81.7172 | G31: 100.012 | H31: 20.71 | L31: 631.2 | M31: 27995 | N31: 82.1756 | O31: 0.56
B32: 3 | C32: 44.6762 | D32: 81.4869 | E32: 6.56642 | F32: 81.4896 | G32: 100.018 | H32: 20.70 | L32: 622.2 | M32: 27796 | N32: 81.5914 | O32: 0.12
A33: 3.2 | B33: 1 | C33: 44.8672 | D33: 40.9674 | E33: 3.28711 | F33: 40.9676 | G33: 100.242 | H33: 20.68 | L33: 307.0 | M33: 13774 | N33: 40.4317 | O33: -1.31 | P33: -3.38 | Q33: 0.11
B34: 2 | C34: 43.8990 | D34: 40.6427 | E34: 3.33293 | F34: 40.6423 | G34: 100.240 | H34: 20.68 | L34: 310.6 | M34: 13634 | N34: 40.0208 | O34: -1.53
B35: 3 | C35: 43.7875 | D35: 40.6952 | E35: 3.34577 | F35: 40.6952 | G35: 100.239 | H35: 20.68 | L35: 312.2 | M35: 13672 | N35: 40.1323 | O35: -1.38
A36: 3.373 | B36: 1 | C36: 44.7092 | D36: 41.7484 | E36: 3.36170 | F36: 41.7498 | G36: 100.228 | H36: 20.67 | L36: 314.7 | M36: 14068 | N36: 41.2947 | O36: -1.09 | P36: -3.24 | Q36: 0.17
B37: 2 | C37: 44.1350 | D37: 41.6073 | E37: 3.39395 | F37: 41.6089 | G37: 100.226 | H37: 20.67 | L37: 316.6 | M37: 13972 | N37: 41.0129 | O37: -1.43
B38: 3 | C38: 44.5701 | D38: 41.6313 | E38: 3.36284 | F38: 41.6339 | G38: 100.228 | H38: 20.66 | L38: 314.1 | M38: 14001 | N38: 41.0981 | O38: -1.29

Sheet 贮存环境电磁兼容后复测
A1: 涡 街 流 量 计 测 量 记 录 (脉冲已知系数)
A2: 委托单位 | B2: / | G2: 型号规格 | H2: LUGB 015YDMEJCX2BB-401N15NN4 | O2: 证书编号 | P2: 2026E70-40-
A3: 样品名称 | B3: 涡街流量计 | G3: 出厂编号 | H3: 2026010023 | O3: 准确度 | P3: 1.0级
A4: 制造单位 | B4: 上海自仪海莱特流量仪表有限公司 | G4: 流量范围 | H4: ( 3.2～32.0 )m^3/h | O4: 外观密封 | P4: 合格
A5: 测量依据 | B5: JJG 1029-2007《涡街流量计》 | G5: 脉冲当量 | H5: 340.673 1/L | O5: 测量结果 | P5: qt≤q＜qmax | Q5: qmin≤q＜qt
A6: 环境温度 | B6: (20-21)℃ | D6: 环境湿度 | E6: (68-70)%RH | O6: 示值误差
A7: 测量介质 | B7: 空气 | D7: 其它 | E7: / | O7: 重 复 性
A8: 介质温度 | B8: 21.02℃ | D8: 介质压力 | E8: 101.383kPa | G8: 脉冲已知 | H8: 涡街流量计
A9: 测量用标准器名称：标准表法气体流量标准装置 扩展不确定度：0.3% 流量范围 m^3/h 证书编号： | O9: 测量结论
A12: 检测 | B12: 序号 | C12: 检测 | D12: 标准表 | E12: 标准表在 | F12: 标准表在 | G12: 被检表 | H12: 被检表 | L12: 频率 | M12: 被测 | N12: 被测体积 | O12: 示值误差 | P12: 示值误差 | Q12: 重复性
A13: 流量点 | C13: 时间 | D13: 示值 | E13: 被检处流量 | F13: 被检处体积 | G13: 压力 | H13: 温度 | M13: 脉冲
A14: m^3/h | C14: s | D14: L | E14: m^3/h | F14: L | G14: kPa | H14: ℃ | L14: Hz | M14: N | N14: L | O14: % | P14: % | Q14: %
A15: 3.315 | B15: 1 | C15: 60.3004 | D15: 55.2790 | E15: 3.30114 | F15: 55.2945 | G15: 101.383 | H15: 21.02 | L15: 308.7 | M15: 18613 | N15: 54.6360 | O15: -1.19 | P15: -1.20 | Q15: 0.10
B16: 2 | C16: 59.2965 | D16: 54.6772 | E16: 3.32130 | F16: 54.7060 | G16: 101.382 | H16: 21.04 | L16: 310.2 | M16: 18394 | N16: 53.9931 | O16: -1.30
B17: 3 | C17: 58.9683 | D17: 54.3792 | E17: 3.32193 | F17: 54.4135 | G17: 101.382 | H17: 21.04 | L17: 310.9 | M17: 18332 | N17: 53.8111 | O17: -1.11

Sheet 打印页
B1: 文件号JDJ/E31T002.2/0-2017
B2: （速度式、容积式、质量式）流量计测量记录单
B4: 器 具 名 称 | C4: =初始!B3 -> 涡街流量计 | I4: 证 书 编 号 | K4: 2026E70-40-000029
B5: 型 号/规 格 | C5: =初始!H2 -> LUGB 015YDMEJCX2BB-401N15NN4 | I5: 制 造 厂 | K5: =初始!B4 -> 上海自仪海莱特流量仪表有限公司
B6: 编 号 | C6: =初始!H3 -> 2026010023 | I6: 环 境 温 度 | K6: =初始!B6 -> (20-21)℃ | L6: 环 境 湿 度 | M6: =初始!E6 -> (68-70)%RH
B7: 大 气 压 力 | C7: (100-101)kPa | G7: 流量范围 | I7: =SUBSTITUTE(初始!H4,"m^3","m³") -> ( 3.2～32 )m³/h
B8: 测 量 地 点 | C8: 张衡路1500号流量大力值楼101室 | J8: 技术依据： | K8: JJG 1029-2007附录A
B9: 准确度等级： | C9: 1 | F9: 级
B10: 标准器编号： | C10: 12B170077、YB12813840
B11: 外观与标识： | C11: 符合要求
B12: 耐压强度： | C12: 符合要求 | F12: （最大工作压力 | I12: 2.5 | J12: MPa）
B13: 仪表系数： | C13: =初始!H5 -> 340.673 1/L
B14: 测量数据： | C14: qmax | E14: =初始!A15 -> 32 | F14: m³/h | G14: qmin | I14: =初始!A33 -> 3.2 | J14: m³/h | K14: qt | L14: =初始!A27 -> 6.4 | M14: m³/h
B15: 检 测 流量点 | C15: 序 号 | E15: 流 量 计 读 数 | G15: 标 准 器 读 数 | I15: 示值误差 | J15: 平 均 示值误差 | K15: 重复性 | L15: 备注
E18: （L） | G18: （L） | I18: （%） | J18: （%） | K18: （%）
B19: qmax | C19: 1 | E19: =初始!N15 -> 389.831 | G19: =初始!F15 -> 388.805 | I19: =(E19-G19)/G19*100 -> 0.2638855 | J19: =AVERAGE(I19:I24) -> 0.16236137 | K19: =STDEV(I19:I24) -> 0.13199427 | L19: /
C20: 2 | E20: =初始!N16 -> 387.750 | G20: =初始!F16 -> 386.766 | I20: =(E20-G20)/G20*100 -> 0.2544174
C21: 3 | E21: =初始!N17 -> 397.748 | G21: =初始!F17 -> 396.502 | I21: =(E21-G21)/G21*100 -> 0.3142481
C22: 4 | E22: =初始!N18 -> 385.094 | G22: =初始!F18 -> 385.132 | I22: =(E22-G22)/G22*100 -> -0.009866747
C23: 5 | E23: =初始!N19 -> 391.534 | G23: =初始!F19 -> 391.305 | I23: =(E23-G23)/G23*100 -> 0.058522125
C24: 6 | E24: =初始!N20 -> 382.232 | G24: =初始!F20 -> 381.877 | I24: =(E24-G24)/G24*100 -> 0.09296187
B25: 0.4qmax | C25: 1 | E25: =初始!N21 -> 156.041 | G25: =初始!F21 -> 155.359 | I25: =(E25-G25)/G25*100 -> 0.43898326 | J25: =AVERAGE(I25:I30) -> 0.36447875 | K25: =STDEV(I25:I30) -> 0.055587423
C26: 2 | E26: =初始!N22 -> 155.448 | G26: =初始!F22 -> 154.912 | I26: =(E26-G26)/G26*100 -> 0.34600289
C27: 3 | E27: =初始!N23 -> 156.628 | G27: =初始!F23 -> 156.116 | I27: =(E27-G27)/G27*100 -> 0.32796126
C28: 4 | E28: =初始!N24 -> 158.322 | G28: =初始!F24 -> 157.861 | I28: =(E28-G28)/G28*100 -> 0.29202906
C29: 5 | E29: =初始!N25 -> 157.459 | G29: =初始!F25 -> 156.802 | I29: =(E29-G29)/G29*100 -> 0.41899976
C30: 6 | E30: =初始!N26 -> 156.810 | G30: =初始!F26 -> 156.243 | I30: =(E30-G30)/G30*100 -> 0.36289626
B31: qt | C31: 1 | E31: =初始!N27 -> 80.8928 | G31: =初始!F27 -> 80.6534 | I31: =(E31-G31)/G31*100 -> 0.29682568 | J31: =AVERAGE(I31:I36) -> 0.31871562 | K31: =STDEV(I31:I36) -> 0.16461149
C32: 2 | E32: =初始!N28 -> 81.5415 | G32: =初始!F28 -> 81.3129 | I32: =(E32-G32)/G32*100 -> 0.2811362
C33: 3 | E33: =初始!N29 -> 82.4809 | G33: =初始!F29 -> 82.3264 | I33: =(E33-G33)/G33*100 -> 0.18766763
C34: 4 | E34: =初始!N30 -> 82.6306 | G34: =初始!F30 -> 82.2516 | I34: =(E34-G34)/G34*100 -> 0.46078131
C35: 5 | E35: =初始!N31 -> 82.1756 | G35: =初始!F31 -> 81.7172 | I35: =(E35-G35)/G35*100 -> 0.56095901
C36: 6 | E36: =初始!N32 -> 81.5914 | G36: =初始!F32 -> 81.4896 | I36: =(E36-G36)/G36*100 -> 0.12492392
B37: qmin | C37: 1 | E37: =初始!N33 -> 40.4317 | G37: =初始!F33 -> 40.9676 | I37: =(E37-G37)/G37*100 -> -1.3081069 | J37: =AVERAGE(I37:I42) -> -1.3383158 | K37: =STDEV(I37:I42) -> 0.14998718
C38: 2 | E38: =初始!N34 -> 40.0208 | G38: =初始!F34 -> 40.6423 | I38: =(E38-G38)/G38*100 -> -1.529195
C39: 3 | E39: =初始!N35 -> 40.1323 | G39: =初始!F35 -> 40.6952 | I39: =(E39-G39)/G39*100 -> -1.3832098
C40: 4 | E40: =初始!N36 -> 41.2947 | G40: =初始!F36 -> 41.7498 | I40: =(E40-G40)/G40*100 -> -1.0900651
C41: 5 | E41: =初始!N37 -> 41.0129 | G41: =初始!F37 -> 41.6089 | I41: =(E41-G41)/G41*100 -> -1.4323859
C42: 6 | E42: =初始!N38 -> 41.0981 | G42: =初始!F38 -> 41.6339 | I42: =(E42-G42)/G42*100 -> -1.286932
B47: 检测人员： | G47: 核验人员： | J47: 检测日期： | K47: 2026.09.01 09:00~2026.09.01 16:00
...
