Workbook

Sheet 降流量
A1: 测试点 | B1: 次数 | C1: 流量(m3/h) | D1: 测试时间(s) | E1: 湿度(%) | F1: 标准器压力(kPa) | G1: 标准器温度(℃) | H1: 标准体积(L) | I1: 被检表压力(kPa) | J1: 被检表温度(℃) | K1: 被检表体积(L) | L1: 示值误差(%) | M1: 平均误差(%) | N1: 极差(%) | O1: 压损(Pa)
A2: qmax | B2: 1 | C2: 2.512687 | D2: 71.5315 | E2: 68.59 | F2: 100.64 | G2: 23.03 | H2: 49.92674 | I2: 100.787 | J2: 21.38 | K2: 50 | L2: 0.15 | M2: 0.15 | N2: 0 | O2: 40
A3: 0.7qmax | B3: 1 | C3: 1.729108 | D3: 62.5434 | E3: 68.85 | F3: 100.777 | G3: 23.03 | H3: 30.04008 | I3: 100.836 | J3: 21.37 | K3: 30 | L3: -0.13 | M3: -0.13 | N3: 0 | O3: 22
A4: 0.4qmax | B4: 1 | C4: 0.994171 | D4: 72.4374 | E4: 69.31 | F4: 100.866 | G4: 23.03 | H4: 20.00421 | I4: 100.866 | J4: 21.36 | K4: 20 | L4: -0.02 | M4: -0.02 | N4: 0 | O4: 10
A5: 0.2qmax | B5: 1 | C5: 0.495513 | D5: 145.2833 | E5: 69.45 | F5: 100.902 | G5: 23.01 | H5: 19.99717 | I5: 100.877 | J5: 21.35 | K5: 20 | L5: 0.01 | M5: 0.01 | N5: 0 | O5: 4
A6: 0.1qmax | B6: 1 | C6: 0.244201 | D6: 294.9185 | E6: 69.75 | F6: 100.915 | G6: 23 | H6: 20.00538 | I6: 100.882 | J6: 21.34 | K6: 20 | L6: -0.03 | M6: -0.03 | N6: 0 | O6: 2
A7: qmax | B7: 1 | C7: 2.512796 | D7: 71.4781 | E7: 69.96 | F7: 100.634 | G7: 22.98 | H7: 49.89164 | I7: 100.78 | J7: 21.34 | K7: 50 | L7: 0.22 | M7: 0.22 | N7: 0 | O7: 40
A8: 0.7qmax | B8: 1 | C8: 1.729241 | D8: 62.4724 | E8: 69.98 | F8: 100.773 | G8: 22.98 | H8: 30.00828 | I8: 100.832 | J8: 21.34 | K8: 30 | L8: -0.03 | M8: -0.03 | N8: 0 | O8: 22
A9: 0.4qmax | B9: 1 | C9: 0.994281 | D9: 72.3663 | E9: 69.81 | F9: 100.862 | G9: 22.98 | H9: 19.98679 | I9: 100.862 | J9: 21.34 | K9: 20 | L9: 0.07 | M9: 0.07 | N9: 0 | O9: 10
A10: 0.2qmax | B10: 1 | C10: 0.495542 | D10: 145.2478 | E10: 69.36 | F10: 100.898 | G10: 22.97 | H10: 19.99344 | I10: 100.873 | J10: 21.32 | K10: 20 | L10: 0.03 | M10: 0.03 | N10: 0 | O10: 4
A11: 0.1qmax | B11: 1 | C11: 0.244196 | D11: 295.025 | E11: 68.58 | F11: 100.905 | G11: 22.95 | H11: 20.01218 | I11: 100.872 | J11: 21.29 | K11: 20 | L11: -0.06 | M11: -0.06 | N11: 0 | O11: 2
A12: qmax | B12: 1 | C12: 2.511233 | D12: 71.5136 | E12: 67.1 | F12: 100.545 | G12: 22.76 | H12: 49.88536 | I12: 100.692 | J12: 21.08 | K12: 50 | L12: 0.23 | M12: 0.23 | N12: 0 | O12: 40
A13: 0.7qmax | B13: 1 | C13: 1.729053 | D13: 62.4901 | E13: 68.15 | F13: 100.757 | G13: 22.94 | H13: 30.01353 | I13: 100.816 | J13: 21.28 | K13: 30 | L13: -0.05 | M13: -0.05 | N13: 0 | O13: 22
... A19: qmin | B19: 1 | C19: 0.015667 | D19: 2300.694 | E19: 67.1 | F19: 100.848 | G19: 22.8 | H19: 10.01218 | I19: 100.812 | J19: 21.1 | K19: 10 | L19: -0.12 | M19: -0.12 | N19: 0 | O19: 1

Sheet 升流量
A1: 测试点 | B1: 次数 | C1: 流量(m3/h) | D1: 测试时间(s) | E1: 湿度(%) | F1: 标准器压力(kPa) | G1: 标准器温度(℃) | H1: 标准体积(L) | I1: 被检表压力(kPa) | J1: 被检表温度(℃) | K1: 被检表体积(L) | L1: 示值误差(%) | M1: 平均误差(%) | N1: 极差(%) | O1: 压损(Pa)
A2: qmin | B2: 1 | C2: 0.015666 | D2: 2299.433 | E2: 66.92 | F2: 100.834 | G2: 22.72 | H2: 10.00645 | I2: 100.798 | J2: 21.01 | K2: 10 | L2: -0.06 | M2: -0.06 | N2: 0 | O2: 1
A3: 5qmin | B3: 1 | C3: 0.081705 | D3: 442.1556 | E3: 67 | F3: 100.813 | G3: 22.67 | H3: 10.03506 | I3: 100.784 | J3: 20.97 | K3: 10 | L3: -0.35 | M3: -0.35 | N3: 0 | O3: 2
A4: 10qmin | B4: 1 | C4: 0.162481 | D4: 444.234 | E4: 67.04 | F4: 100.795 | G4: 22.65 | H4: 20.04984 | I4: 100.776 | J4: 20.97 | K4: 20 | L4: -0.25 | M4: -0.25 | N4: 0 | O4: 2
A5: 0.1qmax | B5: 1 | C5: 0.24405 | D5: 295.1671 | E5: 67.11 | F5: 100.805 | G5: 22.64 | H5: 20.00984 | I5: 100.772 | J5: 20.96 | K5: 20 | L5: -0.05 | M5: -0.05 | N5: 0 | O5: 2
A6: 0.2qmax | B6: 1 | C6: 0.495482 | D6: 145.2833 | E6: 67.04 | F6: 100.83 | G6: 22.59 | H6: 19.99592 | I6: 100.805 | J6: 20.94 | K6: 20 | L6: 0.02 | M6: 0.02 | N6: 0 | O6: 4
A7: 0.4qmax | B7: 1 | C7: 0.993732 | D7: 72.5261 | E7: 67.25 | F7: 100.776 | G7: 22.64 | H7: 20.01986 | I7: 100.776 | J7: 20.98 | K7: 20 | L7: -0.1 | M7: -0.1 | N7: 0 | O7: 10
A8: 0.7qmax | B8: 1 | C8: 1.728439 | D8: 62.4902 | E8: 67.27 | F8: 100.688 | G8: 22.63 | H8: 30.00291 | I8: 100.747 | J8: 20.98 | K8: 30 | L8: -0.01 | M8: -0.01 | N8: 0 | O8: 22
A9: qmax | B9: 1 | C9: 2.511937 | D9: 71.6203 | E9: 67.27 | F9: 100.548 | G9: 22.63 | H9: 49.97379 | I9: 100.695 | J9: 20.99 | K9: 50 | L9: 0.05 | M9: 0.05 | N9: 0 | O9: 40
A10: 0.1qmax | B10: 1 | C10: 0.244107 | D10: 295.0784 | E10: 67.34 | F10: 100.818 | G10: 22.63 | H10: 20.00849 | I10: 100.785 | J10: 20.96 | K10: 20 | L10: -0.04 | M10: -0.04 | N10: 0 | O10: 2
A11: 0.2qmax | B11: 1 | C11: 0.495307 | D11: 145.3543 | E11: 67.41 | F11: 100.804 | G11: 22.62 | H11: 19.9986 | I11: 100.779 | J11: 20.96 | K11: 20 | L11: 0.01 | M11: 0.01 | N11: 0 | O11: 4
A12: 0.4qmax | B12: 1 | C12: 0.993767 | D12: 72.4907 | E12: 67.34 | F12: 100.773 | G12: 22.62 | H12: 20.0108 | I12: 100.774 | J12: 20.96 | K12: 20 | L12: -0.05 | M12: -0.05 | N12: 0 | O12: 10
A13: 0.7qmax | B13: 1 | C13: 1.728633 | D13: 62.5079 | E13: 67.3 | F13: 100.695 | G13: 22.62 | H13: 30.01478 | I13: 100.753 | J13: 20.97 | K13: 30 | L13: -0.05 | M13: -0.05 | N13: 0 | O13: 22
... A19: qmax | B19: 1 | C19: 2.512513 | D19: 71.5315 | E19: 67.18 | F19: 100.562 | G19: 22.59 | H19: 49.92329 | I19: 100.708 | J19: 20.96 | K19: 50 | L19: 0.15 | M19: 0.15 | N19: 0 | O19: 40

Sheet 重复性
A1: 测试点 | B1: 次数 | C1: 流量(m3/h) | D1: 测试时间(s) | E1: 湿度(%) | F1: 标准器压力(kPa) | G1: 标准器温度(℃) | H1: 标准体积(L) | I1: 被检表压力(kPa) | J1: 被检表温度(℃) | K1: 被检表体积(L) | L1: 示值误差(%) | M1: 平均误差(%) | N1: 极差(%) | O1: 压损(Pa)
A2: qmax | B2: 1 | C2: 2.522596 | D2: 71.3537 | E2: 69.5 | F2: 101.076 | G2: 22.83 | H2: 49.99903 | I2: 101.222 | J2: 21.76 | K2: 50 | L2: 0 | M2: 0.04 | N2: 0.08 | O2: 38
B3: 2 | C3: 2.522579 | D3: 71.3182 | E3: 69.42 | F3: 101.072 | G3: 22.82 | H3: 49.97383 | I3: 101.219 | J3: 21.75 | K3: 50 | L3: 0.05 | O3: 38
B4: 3 | C4: 2.522634 | D4: 71.3004 | E4: 69.33 | F4: 101.073 | G4: 22.82 | H4: 49.96244 | I4: 101.218 | J4: 21.74 | K4: 50 | L4: 0.08 | O4: 38
A5: 0.1qmax | B5: 1 | C5: 0.245188 | D5: 293.7993 | E5: 68.77 | F5: 101.358 | G5: 22.8 | H5: 20.01001 | I5: 101.326 | J5: 21.71 | K5: 20 | L5: -0.05 | M5: -0.06 | N5: 0.01 | O5: 2
B6: 2 | C6: 0.245195 | D6: 293.817 | E6: 68.27 | F6: 101.36 | G6: 22.78 | H6: 20.01176 | I6: 101.327 | J6: 21.66 | K6: 20 | L6: -0.06 | O6: 2
B7: 3 | C7: 0.245202 | D7: 293.7994 | E7: 68.04 | F7: 101.362 | G7: 22.76 | H7: 20.01114 | I7: 101.329 | J7: 21.62 | K7: 20 | L7: -0.06 | O7: 2
A8: qmin | B8: 1 | C8: 0.015753 | D8: 2282.842 | E8: 67.8 | F8: 101.365 | G8: 22.68 | H8: 9.989313 | I8: 101.329 | J8: 21.45 | K8: 10 | L8: 0.11 | M8: 0.04 | N8: 0.18 | O8: 1
B9: 2 | C9: 0.015752 | D9: 2283.534 | E9: 67.95 | F9: 101.356 | G9: 22.61 | H9: 9.991909 | I9: 101.32 | J9: 21.23 | K9: 10 | L9: 0.08 | O9: 1
B10: 3 | C10: 0.015747 | D10: 2287.78 | E10: 68.16 | F10: 101.318 | G10: 22.56 | H10: 10.00725 | I10: 101.282 | J10: 21.07 | K10: 10 | L10: -0.07 | O10: 1

Sheet 用户模式
A1: 编号 | B1: 起始值 | C1: 终点值 | D1: 表体积 | E1: 标准流量 | F1: 初始时间 | G1: 结束时间 | H1: 时间差 | I1: 时间(时） | J1: 误差(%) | K1: 分 | L1: 秒
A2: 128 | B2: 6.4804 | C2: 6.9034 | D2: =C2-B2 -> 0.423 | E2: 2.5222 | F2: 0.37585648 | G2: 0.38283565 | H2: =G2-F2 -> 0.0069791667 | I2: =(K2+L2/60)/60 -> 0.1675 | J2: =(D2-E2*I2)/(E2*I2)*100 -> 0.1258082 | K2: 10 | L2: 3

Sheet 温度适应性
A1: 高温
A2: 编号：
A3: 流量点 | B3: 燃气表读数 | C3: 标准器读数 | D3: 压力 | E3: 温度 | F3: Vref | G3: 误差
A4: qmax | D4: 102.134 | E4: 38.73 | F4: =C4*D4/101.325*293.15/(E4+273.15) -> 0 | G4: =B4/F4-1 -> #DIV/0!
D5: 102.126 | E5: 38.22 | F5: =C5*D5/101.325*293.15/(E5+273.15) -> 0 | G5: =B5/F5-1 -> #DIV/0!
A6: 0.7qmax | D6: 102.17 | E6: 38.28 | F6: =C6*D6/101.325*293.15/(E6+273.15) -> 0 | G6: =B6/F6-1 -> #DIV/0!
D7: 102.17 | E7: 38.46 | F7: =C7*D7/101.325*293.15/(E7+273.15) -> 0 | G7: =B7/F7-1 -> #DIV/0!
A8: 0.2qmax | D8: 102.188 | E8: 38.99 | F8: =C8*D8/101.325*293.15/(E8+273.15) -> 0 | G8: =B8/F8-1 -> #DIV/0!
D9: 102.184 | E9: 39.43 | F9: =C9*D9/101.325*293.15/(E9+273.15) -> 0 | G9: =B9/F9-1 -> #DIV/0!
A11: 低温
A12: 编号：
A13: 流量点 | B13: 燃气表读数 | C13: 标准器读数 | D13: 压力 | E13: 温度 | F13: Vref | G13: 误差
A14: qmax | D14: 102.001 | E14: -8.89 | F14: =C14*D14/101.325*293.15/(E14+273.15) -> 0 | G14: =B14/F14-1 -> #DIV/0!
D15: 101.996 | E15: -8.89 | F15: =C15*D15/101.325*293.15/(E15+273.15) -> 0 | G15: =B15/F15-1 -> #DIV/0!
A16: 0.7qmax | D16: 102.028 | E16: -8.91 | F16: =C16*D16/101.325*293.15/(E16+273.15) -> 0 | G16: =B16/F16-1 -> #DIV/0!
D17: 102.015 | E17: -8.92 | F17: =C17*D17/101.325*293.15/(E17+273.15) -> 0 | G17: =B17/F17-1 -> #DIV/0!
A18: 0.2qmax | D18: 102.059 | E18: -8.92 | F18: =C18*D18/101.325*293.15/(E18+273.15) -> 0 | G18: =B18/F18-1 -> #DIV/0!
D19: 102.068 | E19: -8.93 | F19: =C19*D19/101.325*293.15/(E19+273.15) -> 0 | G19: =B19/F19-1 -> #DIV/0!

Sheet 环适复测
A1: 测试点 | B1: 次数 | C1: 流量(m3/h) | D1: 测试时间(s) | E1: 湿度(%) | F1: 标准器压力(kPa) | G1: 标准器温度(℃) | H1: 标准体积(L) | I1: 被检表压力(kPa) | J1: 被检表温度(℃) | K1: 被检表体积(L) | L1: 示值误差(%) | M1: 平均误差(%) | N1: 极差(%) | O1: 压损(Pa)
A2: qmax | B2: 1 | C2: 2.552767 | D2: 70.5012 | E2: 58.54 | F2: 101.894 | G2: 20.61 | H2: 49.99254 | I2: 102.043 | J2: 20.43 | K2: 50 | L2: 0.01 | M2: 0.01 | N2: 0 | O2: 40
A3: 0.2qmax | B3: 1 | C3: 0.50336 | D3: 143.0096 | E3: 59.76 | F3: 102.159 | G3: 20.63 | H3: 19.99593 | I3: 102.135 | J3: 20.42 | K3: 20 | L3: 0.02 | M3: 0.02 | N3: 0 | O3: 4
A4: qmin | B4: 1 | C4: 0.015929 | D4: 2255.986 | E4: 62.87 | F4: 102.172 | G4: 20.73 | H4: 9.982231 | I4: 102.136 | J4: 20.45 | K4: 10 | L4: 0.18 | M4: 0.18 | N4: 0 | O4: 2
A5: qmax | B5: 1 | C5: 2.55135 | D5: 70.4123 | E5: 63.53 | F5: 101.857 | G5: 20.81 | H5: 49.90178 | I5: 102.007 | J5: 20.49 | K5: 50 | L5: 0.2 | M5: 0.2 | N5: 0 | O5: 40
A6: 0.2qmax | B6: 1 | C6: 0.503123 | D6: 142.8852 | E6: 64.96 | F6: 102.127 | G6: 20.83 | H6: 19.96913 | I6: 102.104 | J6: 20.49 | K6: 20 | L6: 0.15 | M6: 0.15 | N6: 0 | O6: 4
A7: qmin | B7: 1 | C7: 0.015913 | D7: 2256.092 | E7: 62.17 | F7: 102.108 | G7: 20.92 | H7: 9.972633 | I7: 102.072 | J7: 20.48 | K7: 10 | L7: 0.27 | M7: 0.27 | N7: 0 | O7: 2

Sheet 流体扰动
A1: 测试点 | B1: 次数 | C1: 流量(m3/h) | D1: 测试时间(s) | E1: 湿度(%) | F1: 标准器压力(kPa) | G1: 标准器温度(℃) | H1: 标准体积(L) | I1: 被检表压力(kPa) | J1: 被检表温度(℃) | K1: 被检表体积(L) | L1: 示值误差(%) | M1: 平均误差(%) | N1: 极差(%) | O1: 压损(Pa)
A2: qmax | B2: 1 | Q2: 前
A3: 0.4qmax | B3: 1
A4: 0.25qmax | B4: 1
A5: qmax | B5: 1
A6: 0.4qmax | B6: 1
A7: 0.25qmax | B7: 1
A9: qmax | B9: 1 | Q9: 后
A10: 0.4qmax | B10: 1
A11: 0.25qmax | B11: 1
A12: qmax | B12: 1
A13: 0.4qmax | B13: 1
A14: 0.25qmax | B14: 1

Sheet 耐久性复测
A1: 测试点 | B1: 次数 | C1: 流量(m3/h) | D1: 测试时间(s) | E1: 湿度(%) | F1: 标准器压力(kPa) | G1: 标准器温度(℃) | H1: 标准体积(L) | I1: 被检表压力(kPa) | J1: 被检表温度(℃) | K1: 被检表体积(L) | L1: 示值误差(%) | M1: 平均误差(%) | N1: 极差(%) | O1: 压损(Pa)
A2: qmax | B2: 1 | C2: 2.53449 | D2: 71.1402 | E2: 62.7 | F2: 100.97 | G2: 19.28 | H2: 50.08447 | I2: 100.94 | J2: 19.97 | K2: 50 | L2: -0.17 | M2: -0.17 | N2: 0 | O2: 37
A3: 0.7qmax | B3: 1 | C3: 1.743974 | D3: 61.9746 | E3: 62.06 | F3: 101.103 | G3: 19.29 | H3: 30.0228 | I3: 101.043 | J3: 19.97 | K3: 30 | L3: -0.08 | M3: -0.08 | N3: 0 | O3: 20
A4: 0.4qmax | B4: 1 | C4: 1.002687 | D4: 71.8685 | E4: 61.55 | F4: 101.192 | G4: 19.29 | H4: 20.01711 | I4: 101.114 | J4: 19.98 | K4: 20 | L4: -0.09 | M4: -0.09 | N4: 0 | O4: 8
A5: 0.2qmax | B5: 1 | C5: 0.499733 | D5: 144.199 | E5: 61.07 | F5: 101.228 | G5: 19.3 | H5: 20.01696 | I5: 101.142 | J5: 19.97 | K5: 20 | L5: -0.08 | M5: -0.08 | N5: 0 | O5: 3
A6: 0.1qmax | B6: 1 | C6: 0.24625 | D6: 292.59 | E6: 60.78 | F6: 101.237 | G6: 19.32 | H6: 20.014 | I6: 101.149 | J6: 19.98 | K6: 20 | L6: -0.07 | M6: -0.07 | N6: 0 | O6: 2
A7: qmax | B7: 1 | C7: 2.534148 | D7: 71.016 | E7: 64 | F7: 100.956 | G7: 19.33 | H7: 49.99029 | I7: 100.926 | J7: 20 | K7: 50 | L7: 0.02 | M7: 0.02 | N7: 0 | O7: 37
A8: 0.7qmax | B8: 1 | C8: 1.743982 | D8: 61.9924 | E8: 66.96 | F8: 101.095 | G8: 19.35 | H8: 30.03157 | I8: 101.037 | J8: 20 | K8: 30 | L8: -0.11 | M8: -0.11 | N8: 0 | O8: 20
A9: 0.4qmax | B9: 1 | C9: 1.002768 | D9: 71.7265 | E9: 70.11 | F9: 101.182 | G9: 19.36 | H9: 19.97918 | I9: 101.103 | J9: 20 | K9: 20 | L9: 0.1 | M9: 0.1 | N9: 0 | O9: 8
A10: 0.2qmax | B10: 1 | C10: 0.499858 | D10: 143.8438 | E10: 73.33 | F10: 101.22 | G10: 19.37 | H10: 19.97265 | I10: 101.134 | J10: 20 | K10: 20 | L10: 0.14 | M10: 0.14 | N10: 0 | O10: 3
A11: 0.1qmax | B11: 1 | C11: 0.246354 | D11: 291.9683 | E11: 77.32 | F11: 101.233 | G11: 19.41 | H11: 19.97989 | I11: 101.145 | J11: 20.03 | K11: 20 | L11: 0.1 | M11: 0.1 | N11: 0 | O11: 1
A12: qmax | B12: 1 | C12: 2.53464 | D12: 70.9804 | E12: 78.36 | F12: 100.946 | G12: 19.42 | H12: 49.97493 | I12: 100.916 | J12: 20.07 | K12: 50 | L12: 0.05 | M12: 0.05 | N12: 0 | O12: 37
A13: 0.7qmax | B13: 1 | C13: 1.744024 | D13: 61.9214 | E13: 78.37 | F13: 101.086 | G13: 19.44 | H13: 29.99789 | I13: 101.028 | J13: 20.08 | K13: 30 | L13: 0.01 | M13: 0.01 | N13: 0 | O13: 20
... A22: qmin | B22: 1 | C22: 0.015784 | D22: 2281.605 | E22: 69.44 | F22: 101.137 | G22: 20.3 | H22: 10.00378 | I22: 101.049 | J22: 20.33 | K22: 10 | L22: -0.04 | M22: -0.04 | N22: 0 | O22: 0

Sheet 振动跌落后
A1: 测试点 | B1: 次数 | C1: 流量(m3/h) | D1: 测试时间(s) | E1: 湿度(%) | F1: 标准器压力(kPa) | G1: 标准器温度(℃) | H1: 标准体积(L) | I1: 被检表压力(kPa) | J1: 被检表温度(℃) | K1: 被检表体积(L) | L1: 示值误差(%) | M1: 平均误差(%) | N1: 极差(%) | O1: 压损(Pa)
A2: qmax | B2: 1
A3: 0.7qmax | B3: 1
A4: 0.4qmax | B4: 1
A5: 0.2qmax | B5: 1
A6: 0.1qmax | B6: 1
A7: qmin | B7: 1
A8: qmax | B8: 1
A9: 0.7qmax | B9: 1
A10: 0.4qmax | B10: 1
A11: 0.2qmax | B11: 1
A12: 0.1qmax | B12: 1
A13: qmin | B13: 1

Sheet 打印页
B1: 文件编号：JDJ/E70T029.1/0-2017
B2: 上海市计量测试技术研究院
B3: 燃气表测量记录单
I4: 证书编号： | K4: 2026E70-40-000006
B5: 送检单位： | C5: 上海真兰仪表科技股份有限公司 | I5: 样品名称： | K5: 超声波燃气表
B6: 制造单位： | C6: 上海真兰仪表科技股份有限公司 | I6: 型号： | K6: UG1.6A LP Z2-NB
B7: 出厂编号： | C7: 2582928128 | G7: 测量介质： | I7: 空气 | J7: 温度： | K7: (20~21)℃ | L7: 湿度： | M7: (65~67)%RH
B8: 大气压力： | C8: (100~101)kPa | G8: 流量范围： | I8: (0.016~2.5)m³/h | K8: 压力损失： | L8: =IF(降流量!C2>5,ROUND(MAX(降流量!O2,降流量!O7,降流量!O12)*0.75,0),MAX(降流量!O2,降流量!O7,降流量!O12))&"Pa" -> 40Pa
B9: 测量地点： | C9: 张衡路1500号大力值楼101室 | I9: 技术依据： | J9: JJF 2012-2022
B10: 标准器编号： | C10: 2816、2006-10-002、712455、712456、712457
B11: 外观： | C11: 符合要求 | G11: 密封性： | I11: 符合要求 | K11: 加权平均误差(±0.6%)： | M11: =(0.4*J17+0.7*J23+0.4*J29+0.2*J35+0.1*J41+10*I12*J47/E12+5*I12*J49/E12+I12*J51/E12)/(0.4+0.7+0.4+0.2+0.1+10*I12/E12+5*I12/E12+I12/E12)/100 -> -0.00027531107
B12: 其它： | C12: qmax: | E12: 2.5 | F12: m³/h | G12: qmin: | I12: 0.016 | J12: m³/h | K12: qt: | L12: 0.25 | M12: m³/h
B13: 检测 流量点 | C13: 序号 | E13: 燃气表 读数 | G13: 标准器 读数 | I13: 示值 误差 | J13: 平均示 值误差 | K13: 复现性误差≤0.5% | L13: 误差曲线
L14: 同号时误差绝对值≤1% | M14: 误差曲线落差
E16: （ L ） | G16: （ L ） | I16: （ % ） | J16: （ % ）
B17: qmax | C17: 1 | D17: 降 流 量 | E17: =降流量!K2 -> 50 | G17: =降流量!H2 -> 49.92674 | I17: =(E17-G17)/G17*100 -> 0.146735 | J17: =AVERAGE(I17:I22) -> 0.1463662 | K17: =STDEV(I17:I22)/100 -> 0.00071382232 | L17: =IF(OR(AND(J17>=0,J23>=0,J29>=0,J35>=0,J41>=0),AND(J17<=0,J23<=0,J29<=0,J35<=0,J41<=0)),FIXED(ABS(J17),2)&"%","/(异号)") -> /(异号) | M17: =(MAX(J17:J41)-MIN(J17:J41))/100 -> 0.0022409881
C18: 2 | E18: =降流量!K7 -> 50 | G18: =降流量!H7 -> 49.89164 | I18: =(E18-G18)/G18*100 -> 0.2171907
C19: 3 | E19: =降流量!K12 -> 50 | G19: =降流量!H12 -> 49.88536 | I19: =(E19-G19)/G19*100 -> 0.2298069
C20: 4 | D20: 升 流 量 | E20: =升流量!K9 -> 50 | G20: =升流量!H9 -> 49.97379 | I20: =(E20-G20)/G20*100 -> 0.052447493
C21: 5 | E21: =升流量!K14 -> 50 | G21: =升流量!H14 -> 49.96085 | I21: =(E21-G21)/G21*100 -> 0.078361357
C22: 6 | E22: =升流量!K19 -> 50 | G22: =升流量!H19 -> 49.92329 | I22: =(E22-G22)/G22*100 -> 0.15365574
B23: 0.7qmax | C23: 1 | D23: 降 流 量 | E23: =降流量!K3 -> 30 | G23: =降流量!H3 -> 30.04008 | I23: =(E23-G23)/G23*100 -> -0.13342175 | J23: =AVERAGE(I23:I28) -> -0.077732609 | K23: =STDEV(I23:I28)/100 -> 0.00074034614 | L23: =IF(OR(AND(J17>=0,J23>=0,J29>=0,J35>=0,J41>=0),AND(J17<=0,J23<=0,J29<=0,J35<=0,J41<=0)),FIXED(ABS(J23),2)&"%","/(异号)") -> /(异号)
C24: 2 | E24: =降流量!K8 -> 30 | G24: =降流量!H8 -> 30.00828 | I24: =(E24-G24)/G24*100 -> -0.027592385
C25: 3 | E25: =降流量!K13 -> 30 | G25: =降流量!H13 -> 30.01353 | I25: =(E25-G25)/G25*100 -> -0.045079669
C26: 4 | D26: 升 流 量 | E26: =升流量!K8 -> 30 | G26: =升流量!H8 -> 30.00291 | I26: =(E26-G26)/G26*100 -> -0.0096990592
C27: 5 | E27: =升流量!K13 -> 30 | G27: =升流量!H13 -> 30.01478 | I27: =(E27-G27)/G27*100 -> -0.049242407
C28: 6 | E28: =升流量!K18 -> 30 | G28: =升流量!H18 -> 30.06053 | I28: =(E28-G28)/G28*100 -> -0.20136039
B29: 0.4qmax | C29: 1 | D29: 降 流 量 | E29: =降流量!K4 -> 20 | G29: =降流量!H4 -> 20.00421 | I29: =(E29-G29)/G29*100 -> -0.02104557 | J29: =AVERAGE(I29:I34) -> -0.054577678 | K29: =STDEV(I29:I34)/100 -> 0.00078056411 | L29: =IF(OR(AND(J17>=0,J23>=0,J29>=0,J35>=0,J41>=0),AND(J17<=0,J23<=0,J29<=0,J35<=0,J41<=0)),FIXED(ABS(J29),2)&"%","/(异号)") -> /(异号)
C30: 2 | E30: =降流量!K9 -> 20 | G30: =降流量!H9 -> 19.98679 | I30: =(E30-G30)/G30*100 -> 0.066093655
C31: 3 | E31: =降流量!K14 -> 20 | G31: =降流量!H14 -> 20.03358 | I31: =(E31-G31)/G31*100 -> -0.16761857
C32: 4 | D32: 升 流 量 | E32: =升流量!K7 -> 20 | G32: =升流量!H7 -> 20.01986 | I32: =(E32-G32)/G32*100 -> -0.099201493
C33: 5 | E33: =升流量!K12 -> 20 | G33: =升流量!H12 -> 20.0108 | I33: =(E33-G33)/G33*100 -> -0.053970856
C34: 6 | E34: =升流量!K17 -> 20 | G34: =升流量!H17 -> 20.01035 | I34: =(E34-G34)/G34*100 -> -0.051723233
B35: 0.2qmax | C35: 1 | D35: 降 流 量 | E35: =降流量!K5 -> 20 | G35: =降流量!H5 -> 19.99717 | I35: =(E35-G35)/G35*100 -> 0.014152003 | J35: =AVERAGE(I35:I40) -> 0.0012819223 | K35: =STDEV(I35:I40)/100 -> 0.00028785649 | L35: =IF(OR(AND(J17>=0,J23>=0,J29>=0,J35>=0,J41>=0),AND(J17<=0,J23<=0,J29<=0,J35<=0,J41<=0)),FIXED(ABS(J35),2)&"%","/(异号)") -> /(异号)
C36: 2 | E36: =降流量!K10 -> 20 | G36: =降流量!H10 -> 19.99344 | I36: =(E36-G36)/G36*100 -> 0.032810762
C37: 3 | E37: =降流量!K15 -> 20 | G37: =降流量!H15 -> 20.00473 | I37: =(E37-G37)/G37*100 -> -0.023644408
C38: 4 | D38: 升 流 量 | E38: =升流量!K6 -> 20 | G38: =升流量!H6 -> 19.99592 | I38: =(E38-G38)/G38*100 -> 0.020404162
C39: 5 | E39: =升流量!K11 -> 20 | G39: =升流量!H11 -> 19.9986 | I39: =(E39-G39)/G39*100 -> 0.00700049
C40: 6 | E40: =升流量!K16 -> 20 | G40: =升流量!H16 -> 20.00861 | I40: =(E40-G40)/G40*100 -> -0.043031475
B41: qt | C41: 1 | D41: 降 流 量 | E41: =降流量!K6 -> 20 | G41: =降流量!H6 -> 20.00538 | I41: =(E41-G41)/G41*100 -> -0.026892766 | J41: =AVERAGE(I41:I46) -> -0.043237923 | K41: =STDEV(I41:I46)/100 -> 0.00014302803 | L41: =IF(OR(AND(J17>=0,J23>=0,J29>=0,J35>=0,J41>=0),AND(J17<=0,J23<=0,J29<=0,J35<=0,J41<=0)),FIXED(ABS(J41),2)&"%","/(异号)") -> /(异号)
...
